WARNING 2017-04-15 16:59:23,135 base 8936 8096 Not Found: /user/modifydepartment/
WARNING 2017-04-15 16:59:59,539 base 6196 7388 Not Found: /user/modifydepartment/
WARNING 2017-04-15 17:11:35,617 base 3144 5364 Not Found: /user/modifydepartment/
WARNING 2017-04-15 17:25:57,464 base 3144 1300 Not Found: /user/modifydepartment/
WARNING 2017-04-15 17:26:13,696 base 3144 2496 Not Found: /user/modifydepartment/
WARNING 2017-04-15 17:26:18,977 base 3144 9108 Not Found: /user/modifydepartment/
WARNING 2017-04-15 17:26:24,196 base 3144 8644 Not Found: /user/modifydepartment/
WARNING 2017-04-15 17:31:34,809 base 3144 9764 Not Found: /user/modifydepartment/
ERROR 2017-04-18 13:14:35,694 base 5210 123145434849280 Internal Server Error: /user/userlist/
Traceback (most recent call last):
  File "/Users/zrd/.pyenv/versions/env2.7.13/lib/python2.7/site-packages/django/core/handlers/base.py", line 149, in get_response
    response = self.process_exception_by_middleware(e, request)
  File "/Users/zrd/.pyenv/versions/env2.7.13/lib/python2.7/site-packages/django/core/handlers/base.py", line 147, in get_response
    response = wrapped_callback(request, *callback_args, **callback_kwargs)
  File "/Users/zrd/.pyenv/versions/env2.7.13/lib/python2.7/site-packages/django/views/generic/base.py", line 68, in view
    return self.dispatch(request, *args, **kwargs)
  File "/Users/zrd/.pyenv/versions/env2.7.13/lib/python2.7/site-packages/django/views/generic/base.py", line 88, in dispatch
    return handler(request, *args, **kwargs)
  File "/Users/zrd/.pyenv/versions/env2.7.13/lib/python2.7/site-packages/django/views/generic/list.py", line 174, in get
    context = self.get_context_data()
  File "/Users/zrd/tmp/opsweb/dashboard/user/__init__.py", line 65, in get_context_data
    context['page_range'] = self.get_page_range(context['page_obj'])
  File "/Users/zrd/tmp/opsweb/dashboard/user/__init__.py", line 72, in get_page_range
    return page_obj.paginator.page_range[start_index: page_obj.number + self.after_index]
TypeError: sequence index must be integer, not 'slice'
WARNING 2017-04-18 13:14:35,847 base 5210 123145434849280 Not Found: /favicon.ico
ERROR 2017-04-18 13:16:36,586 base 5221 123145349083136 Internal Server Error: /user/userlist/
Traceback (most recent call last):
  File "/Users/zrd/.pyenv/versions/env2.7.13/lib/python2.7/site-packages/django/core/handlers/base.py", line 149, in get_response
    response = self.process_exception_by_middleware(e, request)
  File "/Users/zrd/.pyenv/versions/env2.7.13/lib/python2.7/site-packages/django/core/handlers/base.py", line 147, in get_response
    response = wrapped_callback(request, *callback_args, **callback_kwargs)
  File "/Users/zrd/.pyenv/versions/env2.7.13/lib/python2.7/site-packages/django/views/generic/base.py", line 68, in view
    return self.dispatch(request, *args, **kwargs)
  File "/Users/zrd/.pyenv/versions/env2.7.13/lib/python2.7/site-packages/django/views/generic/base.py", line 88, in dispatch
    return handler(request, *args, **kwargs)
  File "/Users/zrd/.pyenv/versions/env2.7.13/lib/python2.7/site-packages/django/views/generic/list.py", line 174, in get
    context = self.get_context_data()
  File "/Users/zrd/tmp/opsweb/dashboard/user/__init__.py", line 65, in get_context_data
    context['page_range'] = self.get_page_range(context['page_obj'])
  File "/Users/zrd/tmp/opsweb/dashboard/user/__init__.py", line 72, in get_page_range
    return page_obj.paginator.page_range[start_index: page_obj.number + self.after_index]
TypeError: sequence index must be integer, not 'slice'
ERROR 2017-04-18 13:16:47,462 base 5221 123145349083136 Internal Server Error: /user/userlist/
Traceback (most recent call last):
  File "/Users/zrd/.pyenv/versions/env2.7.13/lib/python2.7/site-packages/django/core/handlers/base.py", line 149, in get_response
    response = self.process_exception_by_middleware(e, request)
  File "/Users/zrd/.pyenv/versions/env2.7.13/lib/python2.7/site-packages/django/core/handlers/base.py", line 147, in get_response
    response = wrapped_callback(request, *callback_args, **callback_kwargs)
  File "/Users/zrd/.pyenv/versions/env2.7.13/lib/python2.7/site-packages/django/views/generic/base.py", line 68, in view
    return self.dispatch(request, *args, **kwargs)
  File "/Users/zrd/.pyenv/versions/env2.7.13/lib/python2.7/site-packages/django/views/generic/base.py", line 88, in dispatch
    return handler(request, *args, **kwargs)
  File "/Users/zrd/.pyenv/versions/env2.7.13/lib/python2.7/site-packages/django/views/generic/list.py", line 174, in get
    context = self.get_context_data()
  File "/Users/zrd/tmp/opsweb/dashboard/user/__init__.py", line 65, in get_context_data
    context['page_range'] = self.get_page_range(context['page_obj'])
  File "/Users/zrd/tmp/opsweb/dashboard/user/__init__.py", line 72, in get_page_range
    return page_obj.paginator.page_range[start_index: page_obj.number + self.after_index]
TypeError: sequence index must be integer, not 'slice'
ERROR 2017-04-18 13:16:55,384 base 5221 123145349083136 Internal Server Error: /user/userlist/
Traceback (most recent call last):
  File "/Users/zrd/.pyenv/versions/env2.7.13/lib/python2.7/site-packages/django/core/handlers/base.py", line 149, in get_response
    response = self.process_exception_by_middleware(e, request)
  File "/Users/zrd/.pyenv/versions/env2.7.13/lib/python2.7/site-packages/django/core/handlers/base.py", line 147, in get_response
    response = wrapped_callback(request, *callback_args, **callback_kwargs)
  File "/Users/zrd/.pyenv/versions/env2.7.13/lib/python2.7/site-packages/django/views/generic/base.py", line 68, in view
    return self.dispatch(request, *args, **kwargs)
  File "/Users/zrd/.pyenv/versions/env2.7.13/lib/python2.7/site-packages/django/views/generic/base.py", line 88, in dispatch
    return handler(request, *args, **kwargs)
  File "/Users/zrd/.pyenv/versions/env2.7.13/lib/python2.7/site-packages/django/views/generic/list.py", line 174, in get
    context = self.get_context_data()
  File "/Users/zrd/tmp/opsweb/dashboard/user/__init__.py", line 65, in get_context_data
    context['page_range'] = self.get_page_range(context['page_obj'])
  File "/Users/zrd/tmp/opsweb/dashboard/user/__init__.py", line 72, in get_page_range
    return page_obj.paginator.page_range[start_index: page_obj.number + self.after_index]
TypeError: sequence index must be integer, not 'slice'
ERROR 2017-04-18 13:18:02,904 base 5229 123145559126016 Internal Server Error: /user/userlist/
Traceback (most recent call last):
  File "/Users/zrd/.pyenv/versions/env2.7.13/lib/python2.7/site-packages/django/core/handlers/base.py", line 149, in get_response
    response = self.process_exception_by_middleware(e, request)
  File "/Users/zrd/.pyenv/versions/env2.7.13/lib/python2.7/site-packages/django/core/handlers/base.py", line 147, in get_response
    response = wrapped_callback(request, *callback_args, **callback_kwargs)
  File "/Users/zrd/.pyenv/versions/env2.7.13/lib/python2.7/site-packages/django/views/generic/base.py", line 68, in view
    return self.dispatch(request, *args, **kwargs)
  File "/Users/zrd/.pyenv/versions/env2.7.13/lib/python2.7/site-packages/django/views/generic/base.py", line 88, in dispatch
    return handler(request, *args, **kwargs)
  File "/Users/zrd/.pyenv/versions/env2.7.13/lib/python2.7/site-packages/django/views/generic/list.py", line 174, in get
    context = self.get_context_data()
  File "/Users/zrd/tmp/opsweb/dashboard/user/__init__.py", line 65, in get_context_data
    context['page_range'] = self.get_page_range(context['page_obj'])
  File "/Users/zrd/tmp/opsweb/dashboard/user/__init__.py", line 72, in get_page_range
    return page_obj.paginator.page_range[start_index: page_obj.number + self.after_index]
TypeError: sequence index must be integer, not 'slice'
ERROR 2017-04-18 13:20:21,412 base 5229 123145559126016 Internal Server Error: /user/userlist/
Traceback (most recent call last):
  File "/Users/zrd/.pyenv/versions/env2.7.13/lib/python2.7/site-packages/django/core/handlers/base.py", line 149, in get_response
    response = self.process_exception_by_middleware(e, request)
  File "/Users/zrd/.pyenv/versions/env2.7.13/lib/python2.7/site-packages/django/core/handlers/base.py", line 147, in get_response
    response = wrapped_callback(request, *callback_args, **callback_kwargs)
  File "/Users/zrd/.pyenv/versions/env2.7.13/lib/python2.7/site-packages/django/views/generic/base.py", line 68, in view
    return self.dispatch(request, *args, **kwargs)
  File "/Users/zrd/.pyenv/versions/env2.7.13/lib/python2.7/site-packages/django/views/generic/base.py", line 88, in dispatch
    return handler(request, *args, **kwargs)
  File "/Users/zrd/.pyenv/versions/env2.7.13/lib/python2.7/site-packages/django/views/generic/list.py", line 174, in get
    context = self.get_context_data()
  File "/Users/zrd/tmp/opsweb/dashboard/user/__init__.py", line 65, in get_context_data
    context['page_range'] = self.get_page_range(context['page_obj'])
  File "/Users/zrd/tmp/opsweb/dashboard/user/__init__.py", line 72, in get_page_range
    return page_obj.paginator.page_range[start_index: page_obj.number + self.after_index]
TypeError: sequence index must be integer, not 'slice'
ERROR 2017-04-18 13:20:31,018 base 5229 123145559126016 Internal Server Error: /user/userlist/
Traceback (most recent call last):
  File "/Users/zrd/.pyenv/versions/env2.7.13/lib/python2.7/site-packages/django/core/handlers/base.py", line 149, in get_response
    response = self.process_exception_by_middleware(e, request)
  File "/Users/zrd/.pyenv/versions/env2.7.13/lib/python2.7/site-packages/django/core/handlers/base.py", line 147, in get_response
    response = wrapped_callback(request, *callback_args, **callback_kwargs)
  File "/Users/zrd/.pyenv/versions/env2.7.13/lib/python2.7/site-packages/django/views/generic/base.py", line 68, in view
    return self.dispatch(request, *args, **kwargs)
  File "/Users/zrd/.pyenv/versions/env2.7.13/lib/python2.7/site-packages/django/views/generic/base.py", line 88, in dispatch
    return handler(request, *args, **kwargs)
  File "/Users/zrd/.pyenv/versions/env2.7.13/lib/python2.7/site-packages/django/views/generic/list.py", line 174, in get
    context = self.get_context_data()
  File "/Users/zrd/tmp/opsweb/dashboard/user/__init__.py", line 65, in get_context_data
    context['page_range'] = self.get_page_range(context['page_obj'])
  File "/Users/zrd/tmp/opsweb/dashboard/user/__init__.py", line 72, in get_page_range
    return page_obj.paginator.page_range[start_index: page_obj.number + self.after_index]
TypeError: sequence index must be integer, not 'slice'
ERROR 2017-04-18 13:48:51,440 base 5435 123145379172352 Internal Server Error: /group/list/
Traceback (most recent call last):
  File "/Users/zrd/.pyenv/versions/env2.7.13/lib/python2.7/site-packages/django/core/handlers/base.py", line 164, in get_response
    response = response.render()
  File "/Users/zrd/.pyenv/versions/env2.7.13/lib/python2.7/site-packages/django/template/response.py", line 158, in render
    self.content = self.rendered_content
  File "/Users/zrd/.pyenv/versions/env2.7.13/lib/python2.7/site-packages/django/template/response.py", line 135, in rendered_content
    content = template.render(context, self._request)
  File "/Users/zrd/.pyenv/versions/env2.7.13/lib/python2.7/site-packages/django/template/backends/django.py", line 74, in render
    return self.template.render(context)
  File "/Users/zrd/.pyenv/versions/env2.7.13/lib/python2.7/site-packages/django/template/base.py", line 210, in render
    return self._render(context)
  File "/Users/zrd/.pyenv/versions/env2.7.13/lib/python2.7/site-packages/django/template/base.py", line 202, in _render
    return self.nodelist.render(context)
  File "/Users/zrd/.pyenv/versions/env2.7.13/lib/python2.7/site-packages/django/template/base.py", line 905, in render
    bit = self.render_node(node, context)
  File "/Users/zrd/.pyenv/versions/env2.7.13/lib/python2.7/site-packages/django/template/debug.py", line 79, in render_node
    return node.render(context)
  File "/Users/zrd/.pyenv/versions/env2.7.13/lib/python2.7/site-packages/django/template/loader_tags.py", line 135, in render
    return compiled_parent._render(context)
  File "/Users/zrd/.pyenv/versions/env2.7.13/lib/python2.7/site-packages/django/template/base.py", line 202, in _render
    return self.nodelist.render(context)
  File "/Users/zrd/.pyenv/versions/env2.7.13/lib/python2.7/site-packages/django/template/base.py", line 905, in render
    bit = self.render_node(node, context)
  File "/Users/zrd/.pyenv/versions/env2.7.13/lib/python2.7/site-packages/django/template/debug.py", line 79, in render_node
    return node.render(context)
  File "/Users/zrd/.pyenv/versions/env2.7.13/lib/python2.7/site-packages/django/template/loader_tags.py", line 65, in render
    result = block.nodelist.render(context)
  File "/Users/zrd/.pyenv/versions/env2.7.13/lib/python2.7/site-packages/django/template/base.py", line 905, in render
    bit = self.render_node(node, context)
  File "/Users/zrd/.pyenv/versions/env2.7.13/lib/python2.7/site-packages/django/template/debug.py", line 79, in render_node
    return node.render(context)
  File "/Users/zrd/.pyenv/versions/env2.7.13/lib/python2.7/site-packages/django/template/defaulttags.py", line 217, in render
    nodelist.append(node.render(context))
  File "/Users/zrd/.pyenv/versions/env2.7.13/lib/python2.7/site-packages/django/template/defaulttags.py", line 329, in render
    return nodelist.render(context)
  File "/Users/zrd/.pyenv/versions/env2.7.13/lib/python2.7/site-packages/django/template/base.py", line 905, in render
    bit = self.render_node(node, context)
  File "/Users/zrd/.pyenv/versions/env2.7.13/lib/python2.7/site-packages/django/template/debug.py", line 79, in render_node
    return node.render(context)
  File "/Users/zrd/.pyenv/versions/env2.7.13/lib/python2.7/site-packages/django/template/defaulttags.py", line 507, in render
    six.reraise(*exc_info)
  File "/Users/zrd/.pyenv/versions/env2.7.13/lib/python2.7/site-packages/django/template/defaulttags.py", line 493, in render
    url = reverse(view_name, args=args, kwargs=kwargs, current_app=current_app)
  File "/Users/zrd/.pyenv/versions/env2.7.13/lib/python2.7/site-packages/django/core/urlresolvers.py", line 578, in reverse
    return force_text(iri_to_uri(resolver._reverse_with_prefix(view, prefix, *args, **kwargs)))
  File "/Users/zrd/.pyenv/versions/env2.7.13/lib/python2.7/site-packages/django/core/urlresolvers.py", line 495, in _reverse_with_prefix
    (lookup_view_s, args, kwargs, len(patterns), patterns))
NoReverseMatch: Reverse for 'group_permissions' with arguments '()' and keyword arguments '{u'gid': u'{{ group.id }}'}' not found. 1 pattern(s) tried: ['group/permissions/$']
ERROR 2017-04-18 13:50:05,649 base 5435 123145379172352 Internal Server Error: /group/list/
Traceback (most recent call last):
  File "/Users/zrd/.pyenv/versions/env2.7.13/lib/python2.7/site-packages/django/core/handlers/base.py", line 164, in get_response
    response = response.render()
  File "/Users/zrd/.pyenv/versions/env2.7.13/lib/python2.7/site-packages/django/template/response.py", line 158, in render
    self.content = self.rendered_content
  File "/Users/zrd/.pyenv/versions/env2.7.13/lib/python2.7/site-packages/django/template/response.py", line 133, in rendered_content
    template = self._resolve_template(self.template_name)
  File "/Users/zrd/.pyenv/versions/env2.7.13/lib/python2.7/site-packages/django/template/response.py", line 88, in _resolve_template
    new_template = self.resolve_template(template)
  File "/Users/zrd/.pyenv/versions/env2.7.13/lib/python2.7/site-packages/django/template/response.py", line 78, in resolve_template
    return loader.select_template(template, using=self.using)
  File "/Users/zrd/.pyenv/versions/env2.7.13/lib/python2.7/site-packages/django/template/loader.py", line 64, in select_template
    return engine.get_template(template_name, dirs)
  File "/Users/zrd/.pyenv/versions/env2.7.13/lib/python2.7/site-packages/django/template/backends/django.py", line 30, in get_template
    return Template(self.engine.get_template(template_name, dirs))
  File "/Users/zrd/.pyenv/versions/env2.7.13/lib/python2.7/site-packages/django/template/engine.py", line 167, in get_template
    template, origin = self.find_template(template_name, dirs)
  File "/Users/zrd/.pyenv/versions/env2.7.13/lib/python2.7/site-packages/django/template/engine.py", line 141, in find_template
    source, display_name = loader(name, dirs)
  File "/Users/zrd/.pyenv/versions/env2.7.13/lib/python2.7/site-packages/django/template/loaders/base.py", line 13, in __call__
    return self.load_template(template_name, template_dirs)
  File "/Users/zrd/.pyenv/versions/env2.7.13/lib/python2.7/site-packages/django/template/loaders/base.py", line 23, in load_template
    template = Template(source, origin, template_name, self.engine)
  File "/Users/zrd/.pyenv/versions/env2.7.13/lib/python2.7/site-packages/django/template/base.py", line 191, in __init__
    self.nodelist = engine.compile_string(template_string, origin)
  File "/Users/zrd/.pyenv/versions/env2.7.13/lib/python2.7/site-packages/django/template/engine.py", line 261, in compile_string
    return parser.parse()
  File "/Users/zrd/.pyenv/versions/env2.7.13/lib/python2.7/site-packages/django/template/base.py", line 342, in parse
    compiled_result = compile_func(self, token)
  File "/Users/zrd/.pyenv/versions/env2.7.13/lib/python2.7/site-packages/django/template/loader_tags.py", line 210, in do_extends
    nodelist = parser.parse()
  File "/Users/zrd/.pyenv/versions/env2.7.13/lib/python2.7/site-packages/django/template/base.py", line 342, in parse
    compiled_result = compile_func(self, token)
  File "/Users/zrd/.pyenv/versions/env2.7.13/lib/python2.7/site-packages/django/template/loader_tags.py", line 184, in do_block
    nodelist = parser.parse(('endblock',))
  File "/Users/zrd/.pyenv/versions/env2.7.13/lib/python2.7/site-packages/django/template/base.py", line 342, in parse
    compiled_result = compile_func(self, token)
  File "/Users/zrd/.pyenv/versions/env2.7.13/lib/python2.7/site-packages/django/template/defaulttags.py", line 872, in do_for
    nodelist_loop = parser.parse(('empty', 'endfor',))
  File "/Users/zrd/.pyenv/versions/env2.7.13/lib/python2.7/site-packages/django/template/base.py", line 342, in parse
    compiled_result = compile_func(self, token)
  File "/Users/zrd/.pyenv/versions/env2.7.13/lib/python2.7/site-packages/django/template/defaulttags.py", line 1014, in do_if
    nodelist = parser.parse(('elif', 'else', 'endif'))
  File "/Users/zrd/.pyenv/versions/env2.7.13/lib/python2.7/site-packages/django/template/base.py", line 342, in parse
    compiled_result = compile_func(self, token)
  File "/Users/zrd/.pyenv/versions/env2.7.13/lib/python2.7/site-packages/django/template/defaulttags.py", line 1456, in url
    kwargs[name] = parser.compile_filter(value)
  File "/Users/zrd/.pyenv/versions/env2.7.13/lib/python2.7/site-packages/django/template/base.py", line 424, in compile_filter
    return FilterExpression(token, self)
  File "/Users/zrd/.pyenv/versions/env2.7.13/lib/python2.7/site-packages/django/template/base.py", line 640, in __init__
    "from '%s'" % (token[upto:], token))
TemplateSyntaxError: Could not parse the remainder: '{{' from '{{'
ERROR 2017-04-18 13:50:57,874 base 5435 123145379172352 Internal Server Error: /group/list/
Traceback (most recent call last):
  File "/Users/zrd/.pyenv/versions/env2.7.13/lib/python2.7/site-packages/django/core/handlers/base.py", line 164, in get_response
    response = response.render()
  File "/Users/zrd/.pyenv/versions/env2.7.13/lib/python2.7/site-packages/django/template/response.py", line 158, in render
    self.content = self.rendered_content
  File "/Users/zrd/.pyenv/versions/env2.7.13/lib/python2.7/site-packages/django/template/response.py", line 133, in rendered_content
    template = self._resolve_template(self.template_name)
  File "/Users/zrd/.pyenv/versions/env2.7.13/lib/python2.7/site-packages/django/template/response.py", line 88, in _resolve_template
    new_template = self.resolve_template(template)
  File "/Users/zrd/.pyenv/versions/env2.7.13/lib/python2.7/site-packages/django/template/response.py", line 78, in resolve_template
    return loader.select_template(template, using=self.using)
  File "/Users/zrd/.pyenv/versions/env2.7.13/lib/python2.7/site-packages/django/template/loader.py", line 64, in select_template
    return engine.get_template(template_name, dirs)
  File "/Users/zrd/.pyenv/versions/env2.7.13/lib/python2.7/site-packages/django/template/backends/django.py", line 30, in get_template
    return Template(self.engine.get_template(template_name, dirs))
  File "/Users/zrd/.pyenv/versions/env2.7.13/lib/python2.7/site-packages/django/template/engine.py", line 167, in get_template
    template, origin = self.find_template(template_name, dirs)
  File "/Users/zrd/.pyenv/versions/env2.7.13/lib/python2.7/site-packages/django/template/engine.py", line 141, in find_template
    source, display_name = loader(name, dirs)
  File "/Users/zrd/.pyenv/versions/env2.7.13/lib/python2.7/site-packages/django/template/loaders/base.py", line 13, in __call__
    return self.load_template(template_name, template_dirs)
  File "/Users/zrd/.pyenv/versions/env2.7.13/lib/python2.7/site-packages/django/template/loaders/base.py", line 23, in load_template
    template = Template(source, origin, template_name, self.engine)
  File "/Users/zrd/.pyenv/versions/env2.7.13/lib/python2.7/site-packages/django/template/base.py", line 191, in __init__
    self.nodelist = engine.compile_string(template_string, origin)
  File "/Users/zrd/.pyenv/versions/env2.7.13/lib/python2.7/site-packages/django/template/engine.py", line 261, in compile_string
    return parser.parse()
  File "/Users/zrd/.pyenv/versions/env2.7.13/lib/python2.7/site-packages/django/template/base.py", line 342, in parse
    compiled_result = compile_func(self, token)
  File "/Users/zrd/.pyenv/versions/env2.7.13/lib/python2.7/site-packages/django/template/loader_tags.py", line 210, in do_extends
    nodelist = parser.parse()
  File "/Users/zrd/.pyenv/versions/env2.7.13/lib/python2.7/site-packages/django/template/base.py", line 342, in parse
    compiled_result = compile_func(self, token)
  File "/Users/zrd/.pyenv/versions/env2.7.13/lib/python2.7/site-packages/django/template/loader_tags.py", line 184, in do_block
    nodelist = parser.parse(('endblock',))
  File "/Users/zrd/.pyenv/versions/env2.7.13/lib/python2.7/site-packages/django/template/base.py", line 342, in parse
    compiled_result = compile_func(self, token)
  File "/Users/zrd/.pyenv/versions/env2.7.13/lib/python2.7/site-packages/django/template/defaulttags.py", line 872, in do_for
    nodelist_loop = parser.parse(('empty', 'endfor',))
  File "/Users/zrd/.pyenv/versions/env2.7.13/lib/python2.7/site-packages/django/template/base.py", line 342, in parse
    compiled_result = compile_func(self, token)
  File "/Users/zrd/.pyenv/versions/env2.7.13/lib/python2.7/site-packages/django/template/defaulttags.py", line 1014, in do_if
    nodelist = parser.parse(('elif', 'else', 'endif'))
  File "/Users/zrd/.pyenv/versions/env2.7.13/lib/python2.7/site-packages/django/template/base.py", line 342, in parse
    compiled_result = compile_func(self, token)
  File "/Users/zrd/.pyenv/versions/env2.7.13/lib/python2.7/site-packages/django/template/defaulttags.py", line 1458, in url
    args.append(parser.compile_filter(value))
  File "/Users/zrd/.pyenv/versions/env2.7.13/lib/python2.7/site-packages/django/template/base.py", line 424, in compile_filter
    return FilterExpression(token, self)
  File "/Users/zrd/.pyenv/versions/env2.7.13/lib/python2.7/site-packages/django/template/base.py", line 640, in __init__
    "from '%s'" % (token[upto:], token))
TemplateSyntaxError: Could not parse the remainder: '=' from 'gid='
WARNING 2017-04-18 13:56:08,696 base 5435 123145379172352 Not Found: /group/permissions/gid=1
WARNING 2017-04-18 13:56:19,969 base 5435 123145379172352 Not Found: /group/permissions/gid=2
WARNING 2017-04-18 13:56:22,785 base 5435 123145379172352 Not Found: /group/permissions/gid=8
WARNING 2017-04-18 13:56:26,017 base 5435 123145379172352 Not Found: /group/permissions/gid=6
WARNING 2017-04-18 13:59:19,067 base 5435 123145379172352 Not Found: /group/permissions/gid=6
ERROR 2017-04-18 14:43:16,898 base 5600 123145588264960 Internal Server Error: /group/permissions/
Traceback (most recent call last):
  File "/Users/zrd/.pyenv/versions/env2.7.13/lib/python2.7/site-packages/django/core/handlers/base.py", line 132, in get_response
    response = wrapped_callback(request, *callback_args, **callback_kwargs)
  File "/Users/zrd/.pyenv/versions/env2.7.13/lib/python2.7/site-packages/django/views/generic/base.py", line 71, in view
    return self.dispatch(request, *args, **kwargs)
  File "/Users/zrd/.pyenv/versions/env2.7.13/lib/python2.7/site-packages/django/views/generic/base.py", line 89, in dispatch
    return handler(request, *args, **kwargs)
  File "/Users/zrd/.pyenv/versions/env2.7.13/lib/python2.7/site-packages/django/views/generic/list.py", line 159, in get
    self.object_list = self.get_queryset()
  File "/Users/zrd/tmp/opsweb/dashboard/user/group.py", line 195, in get_queryset
    permission = Group.permissions.all()
AttributeError: 'ReverseManyRelatedObjectsDescriptor' object has no attribute 'all'
ERROR 2017-04-18 14:44:00,801 base 5667 123145428238336 Internal Server Error: /group/permissions/
Traceback (most recent call last):
  File "/Users/zrd/.pyenv/versions/env2.7.13/lib/python2.7/site-packages/django/core/handlers/base.py", line 132, in get_response
    response = wrapped_callback(request, *callback_args, **callback_kwargs)
  File "/Users/zrd/.pyenv/versions/env2.7.13/lib/python2.7/site-packages/django/views/generic/base.py", line 71, in view
    return self.dispatch(request, *args, **kwargs)
  File "/Users/zrd/.pyenv/versions/env2.7.13/lib/python2.7/site-packages/django/views/generic/base.py", line 89, in dispatch
    return handler(request, *args, **kwargs)
  File "/Users/zrd/.pyenv/versions/env2.7.13/lib/python2.7/site-packages/django/views/generic/list.py", line 159, in get
    self.object_list = self.get_queryset()
  File "/Users/zrd/tmp/opsweb/dashboard/user/group.py", line 195, in get_queryset
    permission = Group.permissions.all()
AttributeError: 'ReverseManyRelatedObjectsDescriptor' object has no attribute 'all'
ERROR 2017-04-18 14:45:10,913 base 5667 123145428238336 Internal Server Error: /group/permissions/
Traceback (most recent call last):
  File "/Users/zrd/.pyenv/versions/env2.7.13/lib/python2.7/site-packages/django/core/handlers/base.py", line 132, in get_response
    response = wrapped_callback(request, *callback_args, **callback_kwargs)
  File "/Users/zrd/.pyenv/versions/env2.7.13/lib/python2.7/site-packages/django/views/generic/base.py", line 71, in view
    return self.dispatch(request, *args, **kwargs)
  File "/Users/zrd/.pyenv/versions/env2.7.13/lib/python2.7/site-packages/django/views/generic/base.py", line 89, in dispatch
    return handler(request, *args, **kwargs)
  File "/Users/zrd/.pyenv/versions/env2.7.13/lib/python2.7/site-packages/django/views/generic/list.py", line 159, in get
    self.object_list = self.get_queryset()
  File "/Users/zrd/tmp/opsweb/dashboard/user/group.py", line 195, in get_queryset
    permission = Group.permissions.all()
AttributeError: 'ReverseManyRelatedObjectsDescriptor' object has no attribute 'all'
ERROR 2017-04-18 14:54:55,913 base 5710 123145374846976 Internal Server Error: /group/permissions/
Traceback (most recent call last):
  File "/Users/zrd/.pyenv/versions/env2.7.13/lib/python2.7/site-packages/django/core/handlers/base.py", line 132, in get_response
    response = wrapped_callback(request, *callback_args, **callback_kwargs)
  File "/Users/zrd/.pyenv/versions/env2.7.13/lib/python2.7/site-packages/django/views/generic/base.py", line 71, in view
    return self.dispatch(request, *args, **kwargs)
  File "/Users/zrd/.pyenv/versions/env2.7.13/lib/python2.7/site-packages/django/views/generic/base.py", line 89, in dispatch
    return handler(request, *args, **kwargs)
  File "/Users/zrd/.pyenv/versions/env2.7.13/lib/python2.7/site-packages/django/views/generic/list.py", line 159, in get
    self.object_list = self.get_queryset()
  File "/Users/zrd/.pyenv/versions/env2.7.13/lib/python2.7/site-packages/django/views/generic/list.py", line 44, in get_queryset
    'cls': self.__class__.__name__
ImproperlyConfigured: GroupPermissionView is missing a QuerySet. Define GroupPermissionView.model, GroupPermissionView.queryset, or override GroupPermissionView.get_queryset().
ERROR 2017-04-18 14:55:17,075 base 5758 123145532735488 Internal Server Error: /group/permissions/
Traceback (most recent call last):
  File "/Users/zrd/.pyenv/versions/env2.7.13/lib/python2.7/site-packages/django/core/handlers/base.py", line 132, in get_response
    response = wrapped_callback(request, *callback_args, **callback_kwargs)
  File "/Users/zrd/.pyenv/versions/env2.7.13/lib/python2.7/site-packages/django/views/generic/base.py", line 71, in view
    return self.dispatch(request, *args, **kwargs)
  File "/Users/zrd/.pyenv/versions/env2.7.13/lib/python2.7/site-packages/django/views/generic/base.py", line 89, in dispatch
    return handler(request, *args, **kwargs)
  File "/Users/zrd/.pyenv/versions/env2.7.13/lib/python2.7/site-packages/django/views/generic/list.py", line 159, in get
    self.object_list = self.get_queryset()
  File "/Users/zrd/.pyenv/versions/env2.7.13/lib/python2.7/site-packages/django/views/generic/list.py", line 44, in get_queryset
    'cls': self.__class__.__name__
ImproperlyConfigured: GroupPermissionView is missing a QuerySet. Define GroupPermissionView.model, GroupPermissionView.queryset, or override GroupPermissionView.get_queryset().
ERROR 2017-04-18 14:56:26,568 base 5758 123145532735488 Internal Server Error: /group/permissions/
Traceback (most recent call last):
  File "/Users/zrd/.pyenv/versions/env2.7.13/lib/python2.7/site-packages/django/core/handlers/base.py", line 132, in get_response
    response = wrapped_callback(request, *callback_args, **callback_kwargs)
  File "/Users/zrd/.pyenv/versions/env2.7.13/lib/python2.7/site-packages/django/views/generic/base.py", line 71, in view
    return self.dispatch(request, *args, **kwargs)
  File "/Users/zrd/.pyenv/versions/env2.7.13/lib/python2.7/site-packages/django/views/generic/base.py", line 89, in dispatch
    return handler(request, *args, **kwargs)
  File "/Users/zrd/.pyenv/versions/env2.7.13/lib/python2.7/site-packages/django/views/generic/list.py", line 159, in get
    self.object_list = self.get_queryset()
  File "/Users/zrd/.pyenv/versions/env2.7.13/lib/python2.7/site-packages/django/views/generic/list.py", line 44, in get_queryset
    'cls': self.__class__.__name__
ImproperlyConfigured: GroupPermissionView is missing a QuerySet. Define GroupPermissionView.model, GroupPermissionView.queryset, or override GroupPermissionView.get_queryset().
ERROR 2017-04-18 14:56:31,106 base 5758 123145532735488 Internal Server Error: /group/permissions/
Traceback (most recent call last):
  File "/Users/zrd/.pyenv/versions/env2.7.13/lib/python2.7/site-packages/django/core/handlers/base.py", line 132, in get_response
    response = wrapped_callback(request, *callback_args, **callback_kwargs)
  File "/Users/zrd/.pyenv/versions/env2.7.13/lib/python2.7/site-packages/django/views/generic/base.py", line 71, in view
    return self.dispatch(request, *args, **kwargs)
  File "/Users/zrd/.pyenv/versions/env2.7.13/lib/python2.7/site-packages/django/views/generic/base.py", line 89, in dispatch
    return handler(request, *args, **kwargs)
  File "/Users/zrd/.pyenv/versions/env2.7.13/lib/python2.7/site-packages/django/views/generic/list.py", line 159, in get
    self.object_list = self.get_queryset()
  File "/Users/zrd/.pyenv/versions/env2.7.13/lib/python2.7/site-packages/django/views/generic/list.py", line 44, in get_queryset
    'cls': self.__class__.__name__
ImproperlyConfigured: GroupPermissionView is missing a QuerySet. Define GroupPermissionView.model, GroupPermissionView.queryset, or override GroupPermissionView.get_queryset().
ERROR 2017-04-18 14:56:46,622 base 5768 123145414873088 Internal Server Error: /group/permissions/
Traceback (most recent call last):
  File "/Users/zrd/.pyenv/versions/env2.7.13/lib/python2.7/site-packages/django/core/handlers/base.py", line 132, in get_response
    response = wrapped_callback(request, *callback_args, **callback_kwargs)
  File "/Users/zrd/.pyenv/versions/env2.7.13/lib/python2.7/site-packages/django/views/generic/base.py", line 71, in view
    return self.dispatch(request, *args, **kwargs)
  File "/Users/zrd/.pyenv/versions/env2.7.13/lib/python2.7/site-packages/django/views/generic/base.py", line 89, in dispatch
    return handler(request, *args, **kwargs)
  File "/Users/zrd/.pyenv/versions/env2.7.13/lib/python2.7/site-packages/django/views/generic/list.py", line 159, in get
    self.object_list = self.get_queryset()
  File "/Users/zrd/.pyenv/versions/env2.7.13/lib/python2.7/site-packages/django/views/generic/list.py", line 44, in get_queryset
    'cls': self.__class__.__name__
ImproperlyConfigured: GroupPermissionView is missing a QuerySet. Define GroupPermissionView.model, GroupPermissionView.queryset, or override GroupPermissionView.get_queryset().
ERROR 2017-04-18 14:57:58,167 base 5775 123145372524544 Internal Server Error: /group/permissions/
Traceback (most recent call last):
  File "/Users/zrd/.pyenv/versions/env2.7.13/lib/python2.7/site-packages/django/core/handlers/base.py", line 132, in get_response
    response = wrapped_callback(request, *callback_args, **callback_kwargs)
  File "/Users/zrd/.pyenv/versions/env2.7.13/lib/python2.7/site-packages/django/views/generic/base.py", line 71, in view
    return self.dispatch(request, *args, **kwargs)
  File "/Users/zrd/.pyenv/versions/env2.7.13/lib/python2.7/site-packages/django/views/generic/base.py", line 89, in dispatch
    return handler(request, *args, **kwargs)
  File "/Users/zrd/.pyenv/versions/env2.7.13/lib/python2.7/site-packages/django/views/generic/list.py", line 159, in get
    self.object_list = self.get_queryset()
  File "/Users/zrd/.pyenv/versions/env2.7.13/lib/python2.7/site-packages/django/views/generic/list.py", line 44, in get_queryset
    'cls': self.__class__.__name__
ImproperlyConfigured: GroupPermissionView is missing a QuerySet. Define GroupPermissionView.model, GroupPermissionView.queryset, or override GroupPermissionView.get_queryset().
ERROR 2017-04-18 14:58:04,571 base 5775 123145372524544 Internal Server Error: /group/permissions/
Traceback (most recent call last):
  File "/Users/zrd/.pyenv/versions/env2.7.13/lib/python2.7/site-packages/django/core/handlers/base.py", line 132, in get_response
    response = wrapped_callback(request, *callback_args, **callback_kwargs)
  File "/Users/zrd/.pyenv/versions/env2.7.13/lib/python2.7/site-packages/django/views/generic/base.py", line 71, in view
    return self.dispatch(request, *args, **kwargs)
  File "/Users/zrd/.pyenv/versions/env2.7.13/lib/python2.7/site-packages/django/views/generic/base.py", line 89, in dispatch
    return handler(request, *args, **kwargs)
  File "/Users/zrd/.pyenv/versions/env2.7.13/lib/python2.7/site-packages/django/views/generic/list.py", line 159, in get
    self.object_list = self.get_queryset()
  File "/Users/zrd/.pyenv/versions/env2.7.13/lib/python2.7/site-packages/django/views/generic/list.py", line 44, in get_queryset
    'cls': self.__class__.__name__
ImproperlyConfigured: GroupPermissionView is missing a QuerySet. Define GroupPermissionView.model, GroupPermissionView.queryset, or override GroupPermissionView.get_queryset().
ERROR 2017-04-18 15:02:18,535 base 5794 123145467187200 Internal Server Error: /group/permissions/
Traceback (most recent call last):
  File "/Users/zrd/.pyenv/versions/env2.7.13/lib/python2.7/site-packages/django/core/handlers/base.py", line 132, in get_response
    response = wrapped_callback(request, *callback_args, **callback_kwargs)
  File "/Users/zrd/.pyenv/versions/env2.7.13/lib/python2.7/site-packages/django/views/generic/base.py", line 71, in view
    return self.dispatch(request, *args, **kwargs)
  File "/Users/zrd/.pyenv/versions/env2.7.13/lib/python2.7/site-packages/django/views/generic/base.py", line 89, in dispatch
    return handler(request, *args, **kwargs)
  File "/Users/zrd/.pyenv/versions/env2.7.13/lib/python2.7/site-packages/django/views/generic/list.py", line 159, in get
    self.object_list = self.get_queryset()
  File "/Users/zrd/.pyenv/versions/env2.7.13/lib/python2.7/site-packages/django/views/generic/list.py", line 44, in get_queryset
    'cls': self.__class__.__name__
ImproperlyConfigured: GroupPermissionView is missing a QuerySet. Define GroupPermissionView.model, GroupPermissionView.queryset, or override GroupPermissionView.get_queryset().
ERROR 2017-04-18 15:03:30,123 base 5794 123145467187200 Internal Server Error: /group/permissions/
Traceback (most recent call last):
  File "/Users/zrd/.pyenv/versions/env2.7.13/lib/python2.7/site-packages/django/core/handlers/base.py", line 132, in get_response
    response = wrapped_callback(request, *callback_args, **callback_kwargs)
  File "/Users/zrd/.pyenv/versions/env2.7.13/lib/python2.7/site-packages/django/views/generic/base.py", line 71, in view
    return self.dispatch(request, *args, **kwargs)
  File "/Users/zrd/.pyenv/versions/env2.7.13/lib/python2.7/site-packages/django/views/generic/base.py", line 89, in dispatch
    return handler(request, *args, **kwargs)
  File "/Users/zrd/.pyenv/versions/env2.7.13/lib/python2.7/site-packages/django/views/generic/list.py", line 159, in get
    self.object_list = self.get_queryset()
  File "/Users/zrd/.pyenv/versions/env2.7.13/lib/python2.7/site-packages/django/views/generic/list.py", line 44, in get_queryset
    'cls': self.__class__.__name__
ImproperlyConfigured: GroupPermissionView is missing a QuerySet. Define GroupPermissionView.model, GroupPermissionView.queryset, or override GroupPermissionView.get_queryset().
ERROR 2017-04-18 15:03:39,758 base 5794 123145467187200 Internal Server Error: /group/permissions/
Traceback (most recent call last):
  File "/Users/zrd/.pyenv/versions/env2.7.13/lib/python2.7/site-packages/django/core/handlers/base.py", line 132, in get_response
    response = wrapped_callback(request, *callback_args, **callback_kwargs)
  File "/Users/zrd/.pyenv/versions/env2.7.13/lib/python2.7/site-packages/django/views/generic/base.py", line 71, in view
    return self.dispatch(request, *args, **kwargs)
  File "/Users/zrd/.pyenv/versions/env2.7.13/lib/python2.7/site-packages/django/views/generic/base.py", line 89, in dispatch
    return handler(request, *args, **kwargs)
  File "/Users/zrd/.pyenv/versions/env2.7.13/lib/python2.7/site-packages/django/views/generic/list.py", line 159, in get
    self.object_list = self.get_queryset()
  File "/Users/zrd/.pyenv/versions/env2.7.13/lib/python2.7/site-packages/django/views/generic/list.py", line 44, in get_queryset
    'cls': self.__class__.__name__
ImproperlyConfigured: GroupPermissionView is missing a QuerySet. Define GroupPermissionView.model, GroupPermissionView.queryset, or override GroupPermissionView.get_queryset().
ERROR 2017-04-18 15:03:42,106 base 5794 123145467187200 Internal Server Error: /group/permissions/
Traceback (most recent call last):
  File "/Users/zrd/.pyenv/versions/env2.7.13/lib/python2.7/site-packages/django/core/handlers/base.py", line 132, in get_response
    response = wrapped_callback(request, *callback_args, **callback_kwargs)
  File "/Users/zrd/.pyenv/versions/env2.7.13/lib/python2.7/site-packages/django/views/generic/base.py", line 71, in view
    return self.dispatch(request, *args, **kwargs)
  File "/Users/zrd/.pyenv/versions/env2.7.13/lib/python2.7/site-packages/django/views/generic/base.py", line 89, in dispatch
    return handler(request, *args, **kwargs)
  File "/Users/zrd/.pyenv/versions/env2.7.13/lib/python2.7/site-packages/django/views/generic/list.py", line 159, in get
    self.object_list = self.get_queryset()
  File "/Users/zrd/.pyenv/versions/env2.7.13/lib/python2.7/site-packages/django/views/generic/list.py", line 44, in get_queryset
    'cls': self.__class__.__name__
ImproperlyConfigured: GroupPermissionView is missing a QuerySet. Define GroupPermissionView.model, GroupPermissionView.queryset, or override GroupPermissionView.get_queryset().
ERROR 2017-04-18 15:03:44,271 base 5794 123145467187200 Internal Server Error: /group/permissions/
Traceback (most recent call last):
  File "/Users/zrd/.pyenv/versions/env2.7.13/lib/python2.7/site-packages/django/core/handlers/base.py", line 132, in get_response
    response = wrapped_callback(request, *callback_args, **callback_kwargs)
  File "/Users/zrd/.pyenv/versions/env2.7.13/lib/python2.7/site-packages/django/views/generic/base.py", line 71, in view
    return self.dispatch(request, *args, **kwargs)
  File "/Users/zrd/.pyenv/versions/env2.7.13/lib/python2.7/site-packages/django/views/generic/base.py", line 89, in dispatch
    return handler(request, *args, **kwargs)
  File "/Users/zrd/.pyenv/versions/env2.7.13/lib/python2.7/site-packages/django/views/generic/list.py", line 159, in get
    self.object_list = self.get_queryset()
  File "/Users/zrd/.pyenv/versions/env2.7.13/lib/python2.7/site-packages/django/views/generic/list.py", line 44, in get_queryset
    'cls': self.__class__.__name__
ImproperlyConfigured: GroupPermissionView is missing a QuerySet. Define GroupPermissionView.model, GroupPermissionView.queryset, or override GroupPermissionView.get_queryset().
ERROR 2017-04-18 15:03:46,247 base 5794 123145467187200 Internal Server Error: /group/permissions/
Traceback (most recent call last):
  File "/Users/zrd/.pyenv/versions/env2.7.13/lib/python2.7/site-packages/django/core/handlers/base.py", line 132, in get_response
    response = wrapped_callback(request, *callback_args, **callback_kwargs)
  File "/Users/zrd/.pyenv/versions/env2.7.13/lib/python2.7/site-packages/django/views/generic/base.py", line 71, in view
    return self.dispatch(request, *args, **kwargs)
  File "/Users/zrd/.pyenv/versions/env2.7.13/lib/python2.7/site-packages/django/views/generic/base.py", line 89, in dispatch
    return handler(request, *args, **kwargs)
  File "/Users/zrd/.pyenv/versions/env2.7.13/lib/python2.7/site-packages/django/views/generic/list.py", line 159, in get
    self.object_list = self.get_queryset()
  File "/Users/zrd/.pyenv/versions/env2.7.13/lib/python2.7/site-packages/django/views/generic/list.py", line 44, in get_queryset
    'cls': self.__class__.__name__
ImproperlyConfigured: GroupPermissionView is missing a QuerySet. Define GroupPermissionView.model, GroupPermissionView.queryset, or override GroupPermissionView.get_queryset().
ERROR 2017-04-18 15:03:47,927 base 5794 123145467187200 Internal Server Error: /group/permissions/
Traceback (most recent call last):
  File "/Users/zrd/.pyenv/versions/env2.7.13/lib/python2.7/site-packages/django/core/handlers/base.py", line 132, in get_response
    response = wrapped_callback(request, *callback_args, **callback_kwargs)
  File "/Users/zrd/.pyenv/versions/env2.7.13/lib/python2.7/site-packages/django/views/generic/base.py", line 71, in view
    return self.dispatch(request, *args, **kwargs)
  File "/Users/zrd/.pyenv/versions/env2.7.13/lib/python2.7/site-packages/django/views/generic/base.py", line 89, in dispatch
    return handler(request, *args, **kwargs)
  File "/Users/zrd/.pyenv/versions/env2.7.13/lib/python2.7/site-packages/django/views/generic/list.py", line 159, in get
    self.object_list = self.get_queryset()
  File "/Users/zrd/.pyenv/versions/env2.7.13/lib/python2.7/site-packages/django/views/generic/list.py", line 44, in get_queryset
    'cls': self.__class__.__name__
ImproperlyConfigured: GroupPermissionView is missing a QuerySet. Define GroupPermissionView.model, GroupPermissionView.queryset, or override GroupPermissionView.get_queryset().
WARNING 2017-04-18 15:03:59,645 base 5794 123145467187200 Not Found: /apple-touch-icon-precomposed.png
WARNING 2017-04-18 15:03:59,661 base 5794 123145467187200 Not Found: /apple-touch-icon.png
WARNING 2017-04-18 15:03:59,755 base 5794 123145467187200 Not Found: /apple-touch-icon-precomposed.png
WARNING 2017-04-18 15:03:59,768 base 5794 123145467187200 Not Found: /apple-touch-icon.png
ERROR 2017-04-18 15:07:52,287 base 5815 123145520742400 Internal Server Error: /group/permissions/
Traceback (most recent call last):
  File "/Users/zrd/.pyenv/versions/env2.7.13/lib/python2.7/site-packages/django/core/handlers/base.py", line 132, in get_response
    response = wrapped_callback(request, *callback_args, **callback_kwargs)
  File "/Users/zrd/.pyenv/versions/env2.7.13/lib/python2.7/site-packages/django/views/generic/base.py", line 71, in view
    return self.dispatch(request, *args, **kwargs)
  File "/Users/zrd/.pyenv/versions/env2.7.13/lib/python2.7/site-packages/django/views/generic/base.py", line 89, in dispatch
    return handler(request, *args, **kwargs)
  File "/Users/zrd/.pyenv/versions/env2.7.13/lib/python2.7/site-packages/django/views/generic/list.py", line 159, in get
    self.object_list = self.get_queryset()
  File "/Users/zrd/.pyenv/versions/env2.7.13/lib/python2.7/site-packages/django/views/generic/list.py", line 44, in get_queryset
    'cls': self.__class__.__name__
ImproperlyConfigured: GroupPermissionView is missing a QuerySet. Define GroupPermissionView.model, GroupPermissionView.queryset, or override GroupPermissionView.get_queryset().
WARNING 2017-04-18 15:07:52,530 base 5815 123145520742400 Not Found: /apple-touch-icon-precomposed.png
WARNING 2017-04-18 15:07:52,545 base 5815 123145520742400 Not Found: /apple-touch-icon.png
WARNING 2017-04-19 10:56:42,496 base 5520 7940 Not Found: /server/list/
WARNING 2017-04-19 10:56:42,615 base 5520 5748 Not Found: /favicon.ico
ERROR 2017-04-19 12:33:08,710 base 11404 9796 Internal Server Error: /group/permissions/
Traceback (most recent call last):
  File "C:\Python27\lib\site-packages\django\core\handlers\base.py", line 151, in get_response
    % (callback.__module__, view_name))
ValueError: The view dashboard.user.group.GroupPermissionView didn't return an HttpResponse object. It returned None instead.
ERROR 2017-04-19 12:33:13,809 base 11404 3996 Internal Server Error: /group/permissions/
Traceback (most recent call last):
  File "C:\Python27\lib\site-packages\django\core\handlers\base.py", line 151, in get_response
    % (callback.__module__, view_name))
ValueError: The view dashboard.user.group.GroupPermissionView didn't return an HttpResponse object. It returned None instead.
ERROR 2017-04-19 12:35:03,809 base 11404 8644 Internal Server Error: /group/permissions/
Traceback (most recent call last):
  File "C:\Python27\lib\site-packages\django\core\handlers\base.py", line 151, in get_response
    % (callback.__module__, view_name))
ValueError: The view dashboard.user.group.GroupPermissionView didn't return an HttpResponse object. It returned None instead.
ERROR 2017-04-19 12:35:05,816 base 11404 10488 Internal Server Error: /group/permissions/
Traceback (most recent call last):
  File "C:\Python27\lib\site-packages\django\core\handlers\base.py", line 151, in get_response
    % (callback.__module__, view_name))
ValueError: The view dashboard.user.group.GroupPermissionView didn't return an HttpResponse object. It returned None instead.
ERROR 2017-04-19 12:35:49,542 base 5600 7784 Internal Server Error: /group/permissions/
Traceback (most recent call last):
  File "C:\Python27\lib\site-packages\django\core\handlers\base.py", line 151, in get_response
    % (callback.__module__, view_name))
ValueError: The view dashboard.user.group.GroupPermissionView didn't return an HttpResponse object. It returned None instead.
ERROR 2017-04-19 12:35:50,823 base 5600 5996 Internal Server Error: /group/permissions/
Traceback (most recent call last):
  File "C:\Python27\lib\site-packages\django\core\handlers\base.py", line 151, in get_response
    % (callback.__module__, view_name))
ValueError: The view dashboard.user.group.GroupPermissionView didn't return an HttpResponse object. It returned None instead.
ERROR 2017-04-19 12:35:59,119 base 5600 5964 Internal Server Error: /group/permissions/
Traceback (most recent call last):
  File "C:\Python27\lib\site-packages\django\core\handlers\base.py", line 151, in get_response
    % (callback.__module__, view_name))
ValueError: The view dashboard.user.group.GroupPermissionView didn't return an HttpResponse object. It returned None instead.
ERROR 2017-04-19 12:36:02,053 base 5600 10064 Internal Server Error: /group/permissions/
Traceback (most recent call last):
  File "C:\Python27\lib\site-packages\django\core\handlers\base.py", line 151, in get_response
    % (callback.__module__, view_name))
ValueError: The view dashboard.user.group.GroupPermissionView didn't return an HttpResponse object. It returned None instead.
ERROR 2017-04-19 12:36:05,678 base 5600 9908 Internal Server Error: /group/permissions/
Traceback (most recent call last):
  File "C:\Python27\lib\site-packages\django\core\handlers\base.py", line 151, in get_response
    % (callback.__module__, view_name))
ValueError: The view dashboard.user.group.GroupPermissionView didn't return an HttpResponse object. It returned None instead.
ERROR 2017-04-19 12:36:06,937 base 5600 6884 Internal Server Error: /group/permissions/
Traceback (most recent call last):
  File "C:\Python27\lib\site-packages\django\core\handlers\base.py", line 151, in get_response
    % (callback.__module__, view_name))
ValueError: The view dashboard.user.group.GroupPermissionView didn't return an HttpResponse object. It returned None instead.
ERROR 2017-04-19 12:36:08,219 base 5600 11256 Internal Server Error: /group/permissions/
Traceback (most recent call last):
  File "C:\Python27\lib\site-packages\django\core\handlers\base.py", line 151, in get_response
    % (callback.__module__, view_name))
ValueError: The view dashboard.user.group.GroupPermissionView didn't return an HttpResponse object. It returned None instead.
ERROR 2017-04-19 12:36:10,140 base 5600 12140 Internal Server Error: /group/permissions/
Traceback (most recent call last):
  File "C:\Python27\lib\site-packages\django\core\handlers\base.py", line 151, in get_response
    % (callback.__module__, view_name))
ValueError: The view dashboard.user.group.GroupPermissionView didn't return an HttpResponse object. It returned None instead.
ERROR 2017-04-19 12:36:12,417 base 5600 10396 Internal Server Error: /group/permissions/
Traceback (most recent call last):
  File "C:\Python27\lib\site-packages\django\core\handlers\base.py", line 151, in get_response
    % (callback.__module__, view_name))
ValueError: The view dashboard.user.group.GroupPermissionView didn't return an HttpResponse object. It returned None instead.
ERROR 2017-04-19 12:36:19,555 base 5600 3780 Internal Server Error: /group/permissions/
Traceback (most recent call last):
  File "C:\Python27\lib\site-packages\django\core\handlers\base.py", line 151, in get_response
    % (callback.__module__, view_name))
ValueError: The view dashboard.user.group.GroupPermissionView didn't return an HttpResponse object. It returned None instead.
ERROR 2017-04-19 12:42:13,183 base 12116 6856 Internal Server Error: /group/permissions/
Traceback (most recent call last):
  File "C:\Python27\lib\site-packages\django\core\handlers\base.py", line 151, in get_response
    % (callback.__module__, view_name))
ValueError: The view dashboard.user.group.GroupPermissionView didn't return an HttpResponse object. It returned None instead.
ERROR 2017-04-19 12:43:00,816 base 9752 1724 Internal Server Error: /group/permissions/
Traceback (most recent call last):
  File "C:\Python27\lib\site-packages\django\core\handlers\base.py", line 151, in get_response
    % (callback.__module__, view_name))
ValueError: The view dashboard.user.group.GroupPermissionView didn't return an HttpResponse object. It returned None instead.
ERROR 2017-04-19 14:18:18,200 base 2326 123145445642240 Internal Server Error: /user/userlist/
Traceback (most recent call last):
  File "/Users/zrd/.pyenv/versions/env2.7.13/lib/python2.7/site-packages/django/core/handlers/base.py", line 164, in get_response
    response = response.render()
  File "/Users/zrd/.pyenv/versions/env2.7.13/lib/python2.7/site-packages/django/template/response.py", line 158, in render
    self.content = self.rendered_content
  File "/Users/zrd/.pyenv/versions/env2.7.13/lib/python2.7/site-packages/django/template/response.py", line 133, in rendered_content
    template = self._resolve_template(self.template_name)
  File "/Users/zrd/.pyenv/versions/env2.7.13/lib/python2.7/site-packages/django/template/response.py", line 88, in _resolve_template
    new_template = self.resolve_template(template)
  File "/Users/zrd/.pyenv/versions/env2.7.13/lib/python2.7/site-packages/django/template/response.py", line 78, in resolve_template
    return loader.select_template(template, using=self.using)
  File "/Users/zrd/.pyenv/versions/env2.7.13/lib/python2.7/site-packages/django/template/loader.py", line 64, in select_template
    return engine.get_template(template_name, dirs)
  File "/Users/zrd/.pyenv/versions/env2.7.13/lib/python2.7/site-packages/django/template/backends/django.py", line 30, in get_template
    return Template(self.engine.get_template(template_name, dirs))
  File "/Users/zrd/.pyenv/versions/env2.7.13/lib/python2.7/site-packages/django/template/engine.py", line 167, in get_template
    template, origin = self.find_template(template_name, dirs)
  File "/Users/zrd/.pyenv/versions/env2.7.13/lib/python2.7/site-packages/django/template/engine.py", line 141, in find_template
    source, display_name = loader(name, dirs)
  File "/Users/zrd/.pyenv/versions/env2.7.13/lib/python2.7/site-packages/django/template/loaders/base.py", line 13, in __call__
    return self.load_template(template_name, template_dirs)
  File "/Users/zrd/.pyenv/versions/env2.7.13/lib/python2.7/site-packages/django/template/loaders/base.py", line 23, in load_template
    template = Template(source, origin, template_name, self.engine)
  File "/Users/zrd/.pyenv/versions/env2.7.13/lib/python2.7/site-packages/django/template/base.py", line 191, in __init__
    self.nodelist = engine.compile_string(template_string, origin)
  File "/Users/zrd/.pyenv/versions/env2.7.13/lib/python2.7/site-packages/django/template/engine.py", line 261, in compile_string
    return parser.parse()
  File "/Users/zrd/.pyenv/versions/env2.7.13/lib/python2.7/site-packages/django/template/base.py", line 342, in parse
    compiled_result = compile_func(self, token)
  File "/Users/zrd/.pyenv/versions/env2.7.13/lib/python2.7/site-packages/django/template/loader_tags.py", line 210, in do_extends
    nodelist = parser.parse()
  File "/Users/zrd/.pyenv/versions/env2.7.13/lib/python2.7/site-packages/django/template/base.py", line 342, in parse
    compiled_result = compile_func(self, token)
  File "/Users/zrd/.pyenv/versions/env2.7.13/lib/python2.7/site-packages/django/template/loader_tags.py", line 184, in do_block
    nodelist = parser.parse(('endblock',))
  File "/Users/zrd/.pyenv/versions/env2.7.13/lib/python2.7/site-packages/django/template/base.py", line 316, in parse
    self.empty_variable(token)
  File "/Users/zrd/.pyenv/versions/env2.7.13/lib/python2.7/site-packages/django/template/base.py", line 387, in empty_variable
    raise self.error(token, "Empty variable tag")
TemplateSyntaxError: Empty variable tag
